<?xml version="1.0"?>
<robot name="marin">
  <link name="base_footprint">
  </link>

  <link name="base">
   <visual>
     <geometry>
       <box size="0.48 0.15 0.10" />
     </geometry>
     <material name="yellow">
       <color rgba="0.8 0.8 0.0 1.0"/>
     </material>
   </visual>
  </link>

  <link name="front_right">
   <visual>
     <geometry>
       <cylinder radius="0.095" length="0.08" />
     </geometry>
     <material name="black">
       <color rgba="0 0 0 2.0"/>
     </material>
   </visual>
  </link>

  <link name="front_left">
   <visual>
     <geometry>
       <cylinder radius="0.095" length="0.08" />
     </geometry>
     <material name="black">
       <color rgba="0 0 0 2.0"/>
     </material>
   </visual>
  </link>

  <link name="rear_right">
   <visual>
     <geometry>
       <cylinder radius="0.095" length="0.08" />
     </geometry>
     <material name="black">
       <color rgba="0 0 0 2.0"/>
     </material>
   </visual>
  </link>

  <link name="rear_left">
   <visual>
     <geometry>
       <cylinder radius="0.095" length="0.08" />
     </geometry>
     <material name="black">
       <color rgba="0 0 0 2.0"/>
     </material>
   </visual>
  </link>

  <joint name="base" type="fixed">
    <parent link="base_footprint"/>
    <child link="base"/>
    <origin rpy="0 0 0" xyz="0.24 0.0 0.095"/>
    <axis xyz="0 0 0"/>
  </joint>

  <joint name="front_right_wheel" type="continuous">
    <parent link="base"/>
    <child link="front_right"/>
    <origin rpy="1.570796 0 0" xyz="0.24 0.15 0"/>
    <axis xyz="1 0 0"/>
  </joint>

  <joint name="front_left_wheel" type="continuous">
    <parent link="base"/>
    <child link="front_left"/>
    <origin rpy="-1.570796 0 0" xyz="0.24 -0.15 0"/>
    <axis xyz="1 0 0"/>
  </joint>

  <joint name="rear_right_wheel" type="continuous">
    <parent link="base"/>
    <child link="rear_right"/>
    <origin rpy="1.570796 0 0" xyz="-0.24 0.15 0"/>
    <axis xyz="1 0 0"/>
  </joint>

  <joint name="rear_left_wheel" type="continuous">
    <parent link="base"/>
    <child link="rear_left"/>
    <origin rpy="-1.570796 0 0" xyz="-0.24 -0.15 0"/>
    <axis xyz="1 0 0"/>
  </joint>
</robot>
